<?xml version="1.0"?>
<robot> 
   
    <material name="white">
        <color rgba="1 1 1 1" />
    </material>

    <material name="red">
        <color rgba="1 0 0 1"/>
    </material>

    <material name="orange">
        <color rgba="1 0.3 0.1 1"/>
    </material>

    <material name="blue">
        <color rgba="0.2 0.2 1 1"/>
    </material>

    <material name="black">
        <color rgba="0 0 0 1"/>
    </material>

    <material name = "silver">
        <color rgba="0.8 0.8 0.8 1"/>
    </material>


    <link name = "base_link">
    </link>

    <joint name="base_footprint_joint" type="fixed">
        <parent link="base_link"/>
        <child link="snake_head_servo"/>
        <origin xyz="0 0 0" rpy = "0 0 0"/>
    </joint>
    
    <link name="snake_head_servo">
        <visual>
            <geometry>
                <box size="0.0407 0.0197 0.0429" />
            </geometry>
            <material name="orange"/>
        </visual>
        <collision>
            <geometry>
                <box size="0.0407 0.0197 0.0429" />
            </geometry>
        </collision>
    </link>
    xmlns:xacro="http://www.ros.org/wiki/xacro" 
    <joint name="joint_1" type="revolute">
        <parent link="snake_head_servo" />
        <child link="snake_body_servo" />
        <origin xyz="0.0207 0 0" />
        <axis xyz="0 0 1" />
        <limit lower="-1.5707" upper="1.5707" />
    </joint>
    
    <link name="snake_body_servo">
        <visual>
            <geometry>
       			<origin xyz = "0.04035 0 0"  rpy = " 0 0 0"/>
                <box size="0.0407 0.0197 0.0429" />
            </geometry>
            <material name="blue"/>
        </visual>
        <collision>
            <geometry>
                <box size="0.0407 0.0197 0.0429" />
            </geometry>
        </collision>
    </link>
    
</robot>